<?xml version="1.0" encoding="utf-8"?>
<!-- This URDF was automatically created by SolidWorks to URDF Exporter! Originally created by Stephen Brawner (brawner@gmail.com) 
     Commit Version: 1.6.0-4-g7f85cfe  Build Version: 1.6.7995.38578
     For more information, please see http://wiki.ros.org/sw_urdf_exporter -->
<robot
  name="medux_in">
  <link
    name="base_link">
    <inertial>
      <origin
        xyz="8.1991E-06 0.98656 -0.086954"
        rpy="0 0 0" />
      <mass
        value="1.6" />
      <inertia
        ixx="0.0012805"
        ixy="-1.3656E-09"
        ixz="-1.702E-07"
        iyy="0.0014401"
        iyz="-3.6106E-08"
        izz="0.0016345" />
    </inertial>
    <visual>
      <origin
        xyz="0 0 0"
        rpy="0 0 0" />
      <geometry>
        <mesh
          filename="package://medusa/meshes/base_link.STL" />
      </geometry>
      <material
        name="">
        <color
          rgba="0.79216 0.81961 0.93333 1" />
      </material>
    </visual>
    <collision>
      <origin
        xyz="0 0 0"
        rpy="0 0 0" />
      <geometry>
        <mesh
          filename="package://medusa/meshes/base_link.STL" />
      </geometry>
    </collision>
  </link>
  <link
    name="pan_Link">
    <inertial>
      <origin
        xyz="-0.0118285338400179 -0.0261988170013136 7.74253961943402E-05"
        rpy="0 0 0" />
      <mass
        value="0.0963022052722061" />
      <inertia
        ixx="2.34213925781283E-05"
        ixy="-1.52459122344394E-07"
        ixz="-1.25811602826164E-07"
        iyy="3.24648923973432E-05"
        iyz="-1.96655179436552E-07"
        izz="4.45511929970947E-05" />
    </inertial>
    <visual>
      <origin
        xyz="0 0 0"
        rpy="0 0 0" />
      <geometry>
        <mesh
          filename="package://medusa/meshes/pan_Link.STL" />
      </geometry>
      <material
        name="">
        <color
          rgba="1 1 1 1" />
      </material>
    </visual>
    <collision>
      <origin
        xyz="0 0 0"
        rpy="0 0 0" />
      <geometry>
        <mesh
          filename="package://medusa/meshes/pan_Link.STL" />
      </geometry>
    </collision>
  </link>
  <joint
    name="pan_joint"
    type="revolute">
    <origin
      xyz="0 0.98903 -0.002"
      rpy="1.5708 0 -1.6072" />
    <parent
      link="base_link" />
    <child
      link="pan_Link" />
    <axis
      xyz="0 0 1" />
    <limit
      lower="-1.57"
      upper="1.57"
      effort="0"
      velocity="0" />
  </joint>
  <link
    name="tilt_Link">
    <inertial>
      <origin
        xyz="-0.00884432479967212 0.000435660039421401 0.0046408733757955"
        rpy="0 0 0" />
      <mass
        value="0.0767741720451825" />
      <inertia
        ixx="1.43943261306964E-05"
        ixy="7.70704727691347E-07"
        ixz="4.25377475393785E-07"
        iyy="2.33285419126366E-05"
        iyz="4.33191167756273E-07"
        izz="3.28588303923382E-05" />
    </inertial>
    <visual>
      <origin
        xyz="0 0 0"
        rpy="0 0 0" />
      <geometry>
        <mesh
          filename="package://medusa/meshes/tilt_Link.STL" />
      </geometry>
      <material
        name="">
        <color
          rgba="0.113725490196078 0.113725490196078 0.113725490196078 1" />
      </material>
    </visual>
    <collision>
      <origin
        xyz="0 0 0"
        rpy="0 0 0" />
      <geometry>
        <mesh
          filename="package://medusa/meshes/tilt_Link.STL" />
      </geometry>
    </collision>
  </link>
  <joint
    name="tilt_joint"
    type="revolute">
    <origin
      xyz="-0.0203 -0.06276 0"
      rpy="1.5708 0 0.0010716" />
    <parent
      link="pan_Link" />
    <child
      link="tilt_Link" />
    <axis
      xyz="0 0 1" />
    <limit
      lower="-1.57"
      upper="1.57"
      effort="0"
      velocity="0" />
  </joint>
  <link
    name="motor_Link">
    <inertial>
      <origin
        xyz="0.00363771694203027 -4.84031217884429E-14 -0.000258995428377817"
        rpy="0 0 0" />
      <mass
        value="0.0090483578625824" />
      <inertia
        ixx="1.57866839015676E-06"
        ixy="-1.8736536211995E-19"
        ixz="-4.66008729710768E-08"
        iyy="2.95091265434574E-06"
        iyz="-6.80256420723492E-21"
        izz="4.46739001874519E-06" />
    </inertial>
    <visual>
      <origin
        xyz="0 0 0"
        rpy="0 0 0" />
      <geometry>
        <mesh
          filename="package://medusa/meshes/motor_Link.STL" />
      </geometry>
      <material
        name="">
        <color
          rgba="1 1 1 1" />
      </material>
    </visual>
    <collision>
      <origin
        xyz="0 0 0"
        rpy="0 0 0" />
      <geometry>
        <mesh
          filename="package://medusa/meshes/motor_Link.STL" />
      </geometry>
    </collision>
  </link>
  <joint
    name="motor_joint"
    type="continuous">
    <origin
      xyz="0 1.0135 -0.2523"
      rpy="-1.5708 -1.549 0" />
    <parent
      link="base_link" />
    <child
      link="motor_Link" />
    <axis
      xyz="0 0 1" />
  </joint>
  <link
    name="trans1_Link">
    <inertial>
      <origin
        xyz="0.0350000024922854 6.15115881407585E-11 3.63174674533617E-06"
        rpy="0 0 0" />
      <mass
        value="0.0127602624789467" />
      <inertia
        ixx="2.69533168742575E-07"
        ixy="-2.41708116713188E-14"
        ixz="-2.00375196199614E-14"
        iyy="3.31670440493315E-06"
        iyz="1.88078176772058E-12"
        izz="3.55270411698295E-06" />
    </inertial>
    <visual>
      <origin
        xyz="0 0 0"
        rpy="0 0 0" />
      <geometry>
        <mesh
          filename="package://medusa/meshes/trans1_Link.STL" />
      </geometry>
      <material
        name="">
        <color
          rgba="1 1 1 1" />
      </material>
    </visual>
    <collision>
      <origin
        xyz="0 0 0"
        rpy="0 0 0" />
      <geometry>
        <mesh
          filename="package://medusa/meshes/trans1_Link.STL" />
      </geometry>
    </collision>
  </link>
  <joint
    name="trans1_joint"
    type="continuous">
    <origin
      xyz="0.035 0 0.0003"
      rpy="0 0 -0.03269" />
    <parent
      link="motor_Link" />
    <child
      link="trans1_Link" />
    <axis
      xyz="0 1 0" />
  </joint>
  <link
    name="trans2_Link">
    <inertial>
      <origin
        xyz="0.0349999975069641 -7.22608908473865E-12 -1.46118672716966E-11"
        rpy="0 0 0" />
      <mass
        value="0.0127602624789467" />
      <inertia
        ixx="2.69533168712542E-07"
        ixy="2.27929628751198E-14"
        ixz="-2.0950672417306E-14"
        iyy="3.31670440496319E-06"
        iyz="-1.88077181749526E-12"
        izz="3.55270411698296E-06" />
    </inertial>
    <visual>
      <origin
        xyz="0 0 0"
        rpy="0 0 0" />
      <geometry>
        <mesh
          filename="package://medusa/meshes/trans2_Link.STL" />
      </geometry>
      <material
        name="">
        <color
          rgba="1 1 1 1" />
      </material>
    </visual>
    <collision>
      <origin
        xyz="0 0 0"
        rpy="0 0 0" />
      <geometry>
        <mesh
          filename="package://medusa/meshes/trans2_Link.STL" />
      </geometry>
    </collision>
  </link>
  <joint
    name="trans2_joint"
    type="continuous">
    <origin
      xyz="0.035 0 0.0048"
      rpy="0 0 3.1307" />
    <parent
      link="motor_Link" />
    <child
      link="trans2_Link" />
    <axis
      xyz="0 1 0" />
  </joint>
  <link
    name="des1_Link">
    <inertial>
      <origin
        xyz="-3.35899144194181E-05 0.0119960295285434 0.000270172693535575"
        rpy="0 0 0" />
      <mass
        value="0.0871606227679131" />
      <inertia
        ixx="2.62894561145803E-05"
        ixy="6.01608784088872E-09"
        ixz="1.16637422575552E-07"
        iyy="5.28730397981721E-05"
        iyz="1.42712107940534E-08"
        izz="3.24830835390945E-05" />
    </inertial>
    <visual>
      <origin
        xyz="0 0 0"
        rpy="0 0 0" />
      <geometry>
        <mesh
          filename="package://medusa/meshes/des1_Link.STL" />
      </geometry>
      <material
        name="">
        <color
          rgba="0.792156862745098 0.819607843137255 0.933333333333333 1" />
      </material>
    </visual>
    <collision>
      <origin
        xyz="0 0 0"
        rpy="0 0 0" />
      <geometry>
        <mesh
          filename="package://medusa/meshes/des1_Link.STL" />
      </geometry>
    </collision>
  </link>
  <joint
    name="des1_joint"
    type="prismatic">
    <origin
      xyz="0 0.98903 -0.13532"
      rpy="-1.5708 0 0" />
    <parent
      link="base_link" />
    <child
      link="des1_Link" />
    <axis
      xyz="0 1 0" />
    <limit
      lower="0"
      upper="0.8"
      effort="0"
      velocity="0" />
  </joint>
  <link
    name="var1_Link">
    <inertial>
      <origin
        xyz="0.0372161139419003 -7.38076266770804E-13 3.21964677141295E-15"
        rpy="0 0 0" />
      <mass
        value="0.00336929740146278" />
      <inertia
        ixx="1.11779338879997E-08"
        ixy="1.39440296720386E-18"
        ixz="-5.39942144843989E-21"
        iyy="1.74156056743116E-06"
        iyz="1.05879118406788E-22"
        izz="1.75049230305152E-06" />
    </inertial>
    <visual>
      <origin
        xyz="0 0 0"
        rpy="0 0 0" />
      <geometry>
        <mesh
          filename="package://medusa/meshes/var1_Link.STL" />
      </geometry>
      <material
        name="">
        <color
          rgba="0.647058823529412 0.619607843137255 0.6 1" />
      </material>
    </visual>
    <collision>
      <origin
        xyz="0 0 0"
        rpy="0 0 0" />
      <geometry>
        <mesh
          filename="package://medusa/meshes/var1_Link.STL" />
      </geometry>
    </collision>
  </link>
  <joint
    name="var1_joint"
    type="revolute">
    <origin
      xyz="0.032641 0.010509 -0.032641"
      rpy="0.72609 0.33133 1.2196" />
    <parent
      link="des1_Link" />
    <child
      link="var1_Link" />
    <axis
      xyz="0 0 1" />
    <limit
      lower="-1.57"
      upper="1.57"
      effort="0"
      velocity="0" />
  </joint>
  <link
    name="var2_Link">
    <inertial>
      <origin
        xyz="0.0372161139414589 3.09752223870419E-14 4.38916697970515E-15"
        rpy="0 0 0" />
      <mass
        value="0.00336929740146275" />
      <inertia
        ixx="1.11779338879994E-08"
        ixy="-1.38723978989431E-19"
        ixz="1.95672873067428E-21"
        iyy="1.74156056743115E-06"
        iyz="-1.57561625863084E-24"
        izz="1.7504923030515E-06" />
    </inertial>
    <visual>
      <origin
        xyz="0 0 0"
        rpy="0 0 0" />
      <geometry>
        <mesh
          filename="package://medusa/meshes/var2_Link.STL" />
      </geometry>
      <material
        name="">
        <color
          rgba="0.843137254901961 0.815686274509804 0.752941176470588 1" />
      </material>
    </visual>
    <collision>
      <origin
        xyz="0 0 0"
        rpy="0 0 0" />
      <geometry>
        <mesh
          filename="package://medusa/meshes/var2_Link.STL" />
      </geometry>
    </collision>
  </link>
  <joint
    name="var2_joint"
    type="revolute">
    <origin
      xyz="0 0.012 -0.046"
      rpy="1.5708 0.4817 1.5708" />
    <parent
      link="des1_Link" />
    <child
      link="var2_Link" />
    <axis
      xyz="0 0 1" />
    <limit
      lower="-1.57"
      upper="1.57"
      effort="0"
      velocity="0" />
    <mimic
      joint="var1_joint"
      multiplier="1"
      offset="0" />
  </joint>
  <link
    name="var3_Link">
    <inertial>
      <origin
        xyz="0.0372161139412611 6.08735284401973E-13 3.33066907387547E-15"
        rpy="0 0 0" />
      <mass
        value="0.0033692974014628" />
      <inertia
        ixx="1.11779338879993E-08"
        ixy="5.58295131966948E-18"
        ixz="1.90644451678159E-21"
        iyy="1.74156056743117E-06"
        iyz="1.05879118406788E-22"
        izz="1.75049230305153E-06" />
    </inertial>
    <visual>
      <origin
        xyz="0 0 0"
        rpy="0 0 0" />
      <geometry>
        <mesh
          filename="package://medusa/meshes/var3_Link.STL" />
      </geometry>
      <material
        name="">
        <color
          rgba="0.843137254901961 0.815686274509804 0.752941176470588 1" />
      </material>
    </visual>
    <collision>
      <origin
        xyz="0 0 0"
        rpy="0 0 0" />
      <geometry>
        <mesh
          filename="package://medusa/meshes/var3_Link.STL" />
      </geometry>
    </collision>
  </link>
  <joint
    name="var3_joint"
    type="revolute">
    <origin
      xyz="-0.032475 0.012 -0.032475"
      rpy="2.4167 0.33437 1.9256" />
    <parent
      link="des1_Link" />
    <child
      link="var3_Link" />
    <axis
      xyz="0 0 1" />
    <limit
      lower="-1.57"
      upper="1.57"
      effort="0"
      velocity="0" />
    <mimic
      joint="var2_joint"
      multiplier="1" />
  </joint>
  <link
    name="var4_Link">
    <inertial>
      <origin
        xyz="0.0372161139414705 -1.38777878078145E-17 0"
        rpy="0 0 0" />
      <mass
        value="0.00336929740146276" />
      <inertia
        ixx="1.11779338879994E-08"
        ixy="4.06832240671956E-20"
        ixz="4.18775676038702E-22"
        iyy="1.74156056743116E-06"
        iyz="9.27204596067714E-24"
        izz="1.75049230305151E-06" />
    </inertial>
    <visual>
      <origin
        xyz="0 0 0"
        rpy="0 0 0" />
      <geometry>
        <mesh
          filename="package://medusa/meshes/var4_Link.STL" />
      </geometry>
      <material
        name="">
        <color
          rgba="0.843137254901961 0.815686274509804 0.752941176470588 1" />
      </material>
    </visual>
    <collision>
      <origin
        xyz="0 0 0"
        rpy="0 0 0" />
      <geometry>
        <mesh
          filename="package://medusa/meshes/var4_Link.STL" />
      </geometry>
    </collision>
  </link>
  <joint
    name="var4_joint"
    type="revolute">
    <origin
      xyz="-0.045937 0.013499 0"
      rpy="-3.1416 0 2.0925" />
    <parent
      link="des1_Link" />
    <child
      link="var4_Link" />
    <axis
      xyz="0 0 1" />
    <limit
      lower="-1.57"
      upper="1.57"
      effort="0"
      velocity="0" />
    <mimic
      joint="var3_joint"
      multiplier="1" />
  </joint>
  <link
    name="var5_Link">
    <inertial>
      <origin
        xyz="0.037216113941585 7.92255150372512E-13 -2.88657986402541E-15"
        rpy="0 0 0" />
      <mass
        value="0.00336929740146277" />
      <inertia
        ixx="1.11779338879995E-08"
        ixy="-4.6702965834577E-17"
        ixz="-7.25809628484654E-21"
        iyy="1.74156056743115E-06"
        iyz="-5.29395592033938E-23"
        izz="1.75049230305151E-06" />
    </inertial>
    <visual>
      <origin
        xyz="0 0 0"
        rpy="0 0 0" />
      <geometry>
        <mesh
          filename="package://medusa/meshes/var5_Link.STL" />
      </geometry>
      <material
        name="">
        <color
          rgba="0.843137254901961 0.815686274509804 0.752941176470588 1" />
      </material>
    </visual>
    <collision>
      <origin
        xyz="0 0 0"
        rpy="0 0 0" />
      <geometry>
        <mesh
          filename="package://medusa/meshes/var5_Link.STL" />
      </geometry>
    </collision>
  </link>
  <joint
    name="var5_joint"
    type="revolute">
    <origin
      xyz="-0.032518 0.012 0.032518"
      rpy="-2.4199 -0.34236 1.9352" />
    <parent
      link="des1_Link" />
    <child
      link="var5_Link" />
    <axis
      xyz="0 0 1" />
    <limit
      lower="-1.57"
      upper="1.57"
      effort="0"
      velocity="0" />
    <mimic
      joint="var4_joint"
      multiplier="1" />
  </joint>
  <link
    name="var6_Link">
    <inertial>
      <origin
        xyz="0.0372161139415077 4.85833595575969E-13 -4.45727268260661E-15"
        rpy="0 0 0" />
      <mass
        value="0.00336929740146273" />
      <inertia
        ixx="1.11779338879989E-08"
        ixy="-2.5750876931327E-17"
        ixz="2.04674421871886E-21"
        iyy="1.74156056743114E-06"
        iyz="2.26599889927076E-24"
        izz="1.75049230305149E-06" />
    </inertial>
    <visual>
      <origin
        xyz="0 0 0"
        rpy="0 0 0" />
      <geometry>
        <mesh
          filename="package://medusa/meshes/var6_Link.STL" />
      </geometry>
      <material
        name="">
        <color
          rgba="0.843137254901961 0.815686274509804 0.752941176470588 1" />
      </material>
    </visual>
    <collision>
      <origin
        xyz="0 0 0"
        rpy="0 0 0" />
      <geometry>
        <mesh
          filename="package://medusa/meshes/var6_Link.STL" />
      </geometry>
    </collision>
  </link>
  <joint
    name="var6_joint"
    type="revolute">
    <origin
      xyz="0 0.012 0.045942"
      rpy="-1.5708 -0.49846 1.5708" />
    <parent
      link="des1_Link" />
    <child
      link="var6_Link" />
    <axis
      xyz="0 0 1" />
    <limit
      lower="-1.57"
      upper="1.57"
      effort="0"
      velocity="0" />
    <mimic
      joint="var5_joint"
      multiplier="1" />
  </joint>
  <link
    name="var7_Link">
    <inertial>
      <origin
        xyz="0.0372161139414895 -4.2854608750531E-14 -6.66133814775094E-16"
        rpy="0 0 0" />
      <mass
        value="0.00336929740146276" />
      <inertia
        ixx="1.11779338879995E-08"
        ixy="1.26436624580262E-20"
        ixz="7.83960425547132E-21"
        iyy="1.74156056743114E-06"
        iyz="-5.29395592033938E-23"
        izz="1.7504923030515E-06" />
    </inertial>
    <visual>
      <origin
        xyz="0 0 0"
        rpy="0 0 0" />
      <geometry>
        <mesh
          filename="package://medusa/meshes/var7_Link.STL" />
      </geometry>
      <material
        name="">
        <color
          rgba="0.843137254901961 0.815686274509804 0.752941176470588 1" />
      </material>
    </visual>
    <collision>
      <origin
        xyz="0 0 0"
        rpy="0 0 0" />
      <geometry>
        <mesh
          filename="package://medusa/meshes/var7_Link.STL" />
      </geometry>
    </collision>
  </link>
  <joint
    name="var7_joint"
    type="revolute">
    <origin
      xyz="0.032527 0.012 0.032527"
      rpy="-0.72658 -0.33006 1.2211" />
    <parent
      link="des1_Link" />
    <child
      link="var7_Link" />
    <axis
      xyz="0 0 1" />
    <limit
      lower="-1.57"
      upper="1.57"
      effort="0"
      velocity="0" />
    <mimic
      joint="var6_joint"
      multiplier="1" />
  </joint>
  <link
    name="var8_Link">
    <inertial>
      <origin
        xyz="0.0372161139414965 -9.9406594067375E-14 -1.11022302462516E-16"
        rpy="0 0 0" />
      <mass
        value="0.00336929740146276" />
      <inertia
        ixx="1.11779338879994E-08"
        ixy="-1.79071326368899E-18"
        ixz="3.28928643878773E-22"
        iyy="1.74156056743116E-06"
        iyz="-6.84068782855437E-24"
        izz="1.75049230305151E-06" />
    </inertial>
    <visual>
      <origin
        xyz="0 0 0"
        rpy="0 0 0" />
      <geometry>
        <mesh
          filename="package://medusa/meshes/var8_Link.STL" />
      </geometry>
      <material
        name="">
        <color
          rgba="0.843137254901961 0.815686274509804 0.752941176470588 1" />
      </material>
    </visual>
    <collision>
      <origin
        xyz="0 0 0"
        rpy="0 0 0" />
      <geometry>
        <mesh
          filename="package://medusa/meshes/var8_Link.STL" />
      </geometry>
    </collision>
  </link>
  <joint
    name="var8_joint"
    type="revolute">
    <origin
      xyz="0.046 0.012 0"
      rpy="0 0 1.0888" />
    <parent
      link="des1_Link" />
    <child
      link="var8_Link" />
    <axis
      xyz="0 0 1" />
    <limit
      lower="-1.57"
      upper="1.57"
      effort="0"
      velocity="0" />
    <mimic
      joint="var7_joint"
      multiplier="1" />
  </joint>
  <link
    name="des2_Link">
    <inertial>
      <origin
        xyz="-3.36265553015573E-05 0.011996025197435 0.000223789664236418"
        rpy="0 0 0" />
      <mass
        value="0.087065648965423" />
      <inertia
        ixx="2.61220393789014E-05"
        ixy="6.01614278362878E-09"
        ixz="1.16918317543917E-07"
        iyy="5.24490776636611E-05"
        iyz="1.43044137799259E-08"
        izz="3.22308660578771E-05" />
    </inertial>
    <visual>
      <origin
        xyz="0 0 0"
        rpy="0 0 0" />
      <geometry>
        <mesh
          filename="package://medusa/meshes/des2_Link.STL" />
      </geometry>
      <material
        name="">
        <color
          rgba="0.792156862745098 0.819607843137255 0.933333333333333 1" />
      </material>
    </visual>
    <collision>
      <origin
        xyz="0 0 0"
        rpy="0 0 0" />
      <geometry>
        <mesh
          filename="package://medusa/meshes/des2_Link.STL" />
      </geometry>
    </collision>
  </link>
  <joint
    name="des2_joint"
    type="prismatic">
    <origin
      xyz="0 0.98903 -0.27531"
      rpy="-1.5708 0 0" />
    <parent
      link="base_link" />
    <child
      link="des2_Link" />
    <axis
      xyz="0 1 0" />
    <limit
      lower="0"
      upper="0.8"
      effort="0"
      velocity="0" />
  </joint>
  <link
    name="vari1_Link">
    <inertial>
      <origin
        xyz="0.0383944192780585 -5.2030602049058E-13 1.77635683940025E-15"
        rpy="0 0 0" />
      <mass
        value="0.00348011285246065" />
      <inertia
        ixx="1.15338878638317E-08"
        ixy="4.63459830131351E-17"
        ixz="5.30429567799629E-22"
        iyy="1.908276947371E-06"
        iyz="0"
        izz="1.91749075999985E-06" />
    </inertial>
    <visual>
      <origin
        xyz="0 0 0"
        rpy="0 0 0" />
      <geometry>
        <mesh
          filename="package://medusa/meshes/vari1_Link.STL" />
      </geometry>
      <material
        name="">
        <color
          rgba="0.647058823529412 0.619607843137255 0.6 1" />
      </material>
    </visual>
    <collision>
      <origin
        xyz="0 0 0"
        rpy="0 0 0" />
      <geometry>
        <mesh
          filename="package://medusa/meshes/vari1_Link.STL" />
      </geometry>
    </collision>
  </link>
  <joint
    name="vari1_joint"
    type="revolute">
    <origin
      xyz="0.033507 0.011425 -0.033507"
      rpy="2.4111 0.31976 -1.2333" />
    <parent
      link="des2_Link" />
    <child
      link="vari1_Link" />
    <axis
      xyz="0 0 1" />
    <limit
      lower="-1.57"
      upper="1.57"
      effort="0"
      velocity="0" />
  </joint>
  <link
    name="vari2_Link">
    <inertial>
      <origin
        xyz="0.0383944192776854 2.89768209427166E-14 2.4737594563612E-15"
        rpy="0 0 0" />
      <mass
        value="0.00348011285246064" />
      <inertia
        ixx="1.15338878638316E-08"
        ixy="7.58102759598724E-20"
        ixz="-2.13161642804239E-21"
        iyy="1.908276947371E-06"
        iyz="-3.50886094916816E-24"
        izz="1.91749075999986E-06" />
    </inertial>
    <visual>
      <origin
        xyz="0 0 0"
        rpy="0 0 0" />
      <geometry>
        <mesh
          filename="package://medusa/meshes/vari2_Link.STL" />
      </geometry>
      <material
        name="">
        <color
          rgba="0.647058823529412 0.619607843137255 0.6 1" />
      </material>
    </visual>
    <collision>
      <origin
        xyz="0 0 0"
        rpy="0 0 0" />
      <geometry>
        <mesh
          filename="package://medusa/meshes/vari2_Link.STL" />
      </geometry>
    </collision>
  </link>
  <joint
    name="vari2_joint"
    type="revolute">
    <origin
      xyz="0 0.012 -0.045944"
      rpy="1.5708 0.4825 -1.5708" />
    <parent
      link="des2_Link" />
    <child
      link="vari2_Link" />
    <axis
      xyz="0 0 1" />
    <limit
      lower="-1.57"
      upper="1.57"
      effort="0"
      velocity="0" />
    <mimic
      joint="vari1_joint"
      multiplier="1"
      offset="0" />
  </joint>
  <link
    name="vari3_Link">
    <inertial>
      <origin
        xyz="0.0383944192776972 1.40276679161389E-13 1.66533453693773E-15"
        rpy="0 0 0" />
      <mass
        value="0.0034801128524607" />
      <inertia
        ixx="1.1533887863832E-08"
        ixy="-7.00655066056917E-18"
        ixz="-5.7654488694946E-22"
        iyy="1.90827694737104E-06"
        iyz="0"
        izz="1.91749075999989E-06" />
    </inertial>
    <visual>
      <origin
        xyz="0 0 0"
        rpy="0 0 0" />
      <geometry>
        <mesh
          filename="package://medusa/meshes/vari3_Link.STL" />
      </geometry>
      <material
        name="">
        <color
          rgba="0.647058823529412 0.619607843137255 0.6 1" />
      </material>
    </visual>
    <collision>
      <origin
        xyz="0 0 0"
        rpy="0 0 0" />
      <geometry>
        <mesh
          filename="package://medusa/meshes/vari3_Link.STL" />
      </geometry>
    </collision>
  </link>
  <joint
    name="vari3_joint"
    type="revolute">
    <origin
      xyz="-0.032527 0.012 -0.032527"
      rpy="0.72518 0.33367 -1.9248" />
    <parent
      link="des2_Link" />
    <child
      link="vari3_Link" />
    <axis
      xyz="0 0 1" />
    <limit
      lower="-1.57"
      upper="1.57"
      effort="0"
      velocity="0" />
    <mimic
      joint="vari2_joint"
      multiplier="1" />
  </joint>
  <link
    name="vari4_Link">
    <inertial>
      <origin
        xyz="0.0383944192776953 2.83106871279415E-15 1.11022302462516E-16"
        rpy="0 0 0" />
      <mass
        value="0.00348011285246065" />
      <inertia
        ixx="1.15338878638319E-08"
        ixy="-4.65603423193848E-20"
        ixz="-4.65890770850715E-22"
        iyy="1.908276947371E-06"
        iyz="-1.00852880211941E-23"
        izz="1.91749075999986E-06" />
    </inertial>
    <visual>
      <origin
        xyz="0 0 0"
        rpy="0 0 0" />
      <geometry>
        <mesh
          filename="package://medusa/meshes/vari4_Link.STL" />
      </geometry>
      <material
        name="">
        <color
          rgba="0.647058823529412 0.619607843137255 0.6 1" />
      </material>
    </visual>
    <collision>
      <origin
        xyz="0 0 0"
        rpy="0 0 0" />
      <geometry>
        <mesh
          filename="package://medusa/meshes/vari4_Link.STL" />
      </geometry>
    </collision>
  </link>
  <joint
    name="vari4_joint"
    type="revolute">
    <origin
      xyz="-0.045956 0.010501 0"
      rpy="0 0 -2.0922" />
    <parent
      link="des2_Link" />
    <child
      link="vari4_Link" />
    <axis
      xyz="0 0 1" />
    <limit
      lower="-1.57"
      upper="1.57"
      effort="0"
      velocity="0" />
    <mimic
      joint="vari3_joint"
      multiplier="1" />
  </joint>
  <link
    name="vari5_Link">
    <inertial>
      <origin
        xyz="0.0383944192776846 2.53796983429311E-13 -1.11022302462516E-15"
        rpy="0 0 0" />
      <mass
        value="0.00348011285246069" />
      <inertia
        ixx="1.15338878638318E-08"
        ixy="-1.30448558084623E-17"
        ixz="-7.26388654913441E-21"
        iyy="1.90827694737102E-06"
        iyz="-5.29395592033938E-23"
        izz="1.91749075999988E-06" />
    </inertial>
    <visual>
      <origin
        xyz="0 0 0"
        rpy="0 0 0" />
      <geometry>
        <mesh
          filename="package://medusa/meshes/vari5_Link.STL" />
      </geometry>
      <material
        name="">
        <color
          rgba="0.647058823529412 0.619607843137255 0.6 1" />
      </material>
    </visual>
    <collision>
      <origin
        xyz="0 0 0"
        rpy="0 0 0" />
      <geometry>
        <mesh
          filename="package://medusa/meshes/vari5_Link.STL" />
      </geometry>
    </collision>
  </link>
  <joint
    name="vari5_joint"
    type="revolute">
    <origin
      xyz="-0.033583 0.011858 0.033583"
      rpy="-0.72734 -0.32809 -1.9181" />
    <parent
      link="des2_Link" />
    <child
      link="vari5_Link" />
    <axis
      xyz="0 0 1" />
    <limit
      lower="-1.57"
      upper="1.57"
      effort="0"
      velocity="0" />
    <mimic
      joint="vari4_joint"
      multiplier="1"
      offset="0" />
  </joint>
  <link
    name="vari6_Link">
    <inertial>
      <origin
        xyz="0.0383944192767571 -1.73638881051374E-13 -2.40786398692195E-15"
        rpy="0 0 0" />
      <mass
        value="0.00348011285246067" />
      <inertia
        ixx="1.15338878638323E-08"
        ixy="-3.57380352036591E-17"
        ixz="-2.21151698286206E-21"
        iyy="1.90827694737102E-06"
        iyz="1.85231217797673E-25"
        izz="1.91749075999987E-06" />
    </inertial>
    <visual>
      <origin
        xyz="0 0 0"
        rpy="0 0 0" />
      <geometry>
        <mesh
          filename="package://medusa/meshes/vari6_Link.STL" />
      </geometry>
      <material
        name="">
        <color
          rgba="0.647058823529412 0.619607843137255 0.6 1" />
      </material>
    </visual>
    <collision>
      <origin
        xyz="0 0 0"
        rpy="0 0 0" />
      <geometry>
        <mesh
          filename="package://medusa/meshes/vari6_Link.STL" />
      </geometry>
    </collision>
  </link>
  <joint
    name="vari6_joint"
    type="revolute">
    <origin
      xyz="0 0.011577 0.047439"
      rpy="-1.5708 -0.477 -1.5708" />
    <parent
      link="des2_Link" />
    <child
      link="vari6_Link" />
    <axis
      xyz="0 0 1" />
    <limit
      lower="-1.57"
      upper="1.57"
      effort="0"
      velocity="0" />
    <mimic
      joint="vari5_joint"
      multiplier="1"
      offset="0" />
  </joint>
  <link
    name="vari7_Link">
    <inertial>
      <origin
        xyz="0.0383944192777346 -6.11732886568461E-14 -2.33146835171283E-15"
        rpy="0 0 0" />
      <mass
        value="0.00348011285246063" />
      <inertia
        ixx="1.15338878638318E-08"
        ixy="2.31368621185676E-20"
        ixz="2.37359476772091E-21"
        iyy="1.90827694737098E-06"
        iyz="1.05879118406788E-22"
        izz="1.91749075999984E-06" />
    </inertial>
    <visual>
      <origin
        xyz="0 0 0"
        rpy="0 0 0" />
      <geometry>
        <mesh
          filename="package://medusa/meshes/vari7_Link.STL" />
      </geometry>
      <material
        name="">
        <color
          rgba="0.647058823529412 0.619607843137255 0.6 1" />
      </material>
    </visual>
    <collision>
      <origin
        xyz="0 0 0"
        rpy="0 0 0" />
      <geometry>
        <mesh
          filename="package://medusa/meshes/vari7_Link.STL" />
      </geometry>
    </collision>
  </link>
  <joint
    name="vari7_joint"
    type="revolute">
    <origin
      xyz="0.03194 0.012 0.03194"
      rpy="-2.4181 -0.33793 -1.2117" />
    <parent
      link="des2_Link" />
    <child
      link="vari7_Link" />
    <axis
      xyz="0 0 1" />
    <limit
      lower="-1.57"
      upper="1.57"
      effort="0"
      velocity="0" />
    <mimic
      joint="vari6_joint"
      multiplier="1" />
  </joint>
  <link
    name="vari8_Link">
    <inertial>
      <origin
        xyz="0.0383944192777002 -4.5102810375397E-14 -1.11022302462516E-16"
        rpy="0 0 0" />
      <mass
        value="0.00348011285246063" />
      <inertia
        ixx="1.15338878638315E-08"
        ixy="1.90273833404705E-18"
        ixz="-6.7182998921553E-22"
        iyy="1.908276947371E-06"
        iyz="3.994916513673E-23"
        izz="1.91749075999986E-06" />
    </inertial>
    <visual>
      <origin
        xyz="0 0 0"
        rpy="0 0 0" />
      <geometry>
        <mesh
          filename="package://medusa/meshes/vari8_Link.STL" />
      </geometry>
      <material
        name="">
        <color
          rgba="0.647058823529412 0.619607843137255 0.6 1" />
      </material>
    </visual>
    <collision>
      <origin
        xyz="0 0 0"
        rpy="0 0 0" />
      <geometry>
        <mesh
          filename="package://medusa/meshes/vari8_Link.STL" />
      </geometry>
    </collision>
  </link>
  <joint
    name="vari8_joint"
    type="revolute">
    <origin
      xyz="0.045982 0.012 0"
      rpy="-3.1416 0 -1.0886" />
    <parent
      link="des2_Link" />
    <child
      link="vari8_Link" />
    <axis
      xyz="0 0 1" />
    <limit
      lower="-1.57"
      upper="1.57"
      effort="0"
      velocity="0" />
    <mimic
      joint="vari7_joint"
      multiplier="1"
      offset="0" />
  </joint>
</robot>
